Workbook
Name FoodList: 'All Foods'!$A$6:$A$505

Sheet All Foods
A1: ALL FOODS — daily summary
A2: Добавяй нова храна или ястие в следващия празен ред. Стойностите в C:K са за 100 g; ястията използват общите суми от своя таб.
A3: DAILY TOTAL | B3: =SUM(B6:B505) -> 1691 | L3: =SUM(L6:L505) -> 2148.12 | M3: =SUM(M6:M505) -> 44.2668 | N3: =SUM(N6:N505) -> 15.4796 | O3: =SUM(O6:O505) -> 171.4134 | P3: =SUM(P6:P505) -> 66.1548 | Q3: =SUM(Q6:Q505) -> 174.9184 | R3: =SUM(R6:R505) -> 22.946 | S3: =SUM(S6:S505) -> 1.95 | T3: =SUM(T6:T505) -> 0.55
A5: food_name | B5: grams_eaten (all meals) | C5: calories / 100g | D5: fat / 100g | E5: saturated_fat / 100g | F5: carbohydrates / 100g | G5: sugars / 100g | H5: protein / 100g | I5: fiber / 100g | J5: omega-3 / 100g | K5: omega-6 / 100g | L5: calories total | M5: fat total | N5: saturated_fat total | O5: carbohydrates total | P5: sugars total | Q5: protein total | R5: fiber total | S5: omega-3 total | T5: omega-6 total
A6: Chia seeds | B6: =IF(A6="","",SUMIF('Table 3 - shake'!$A$4:$A$505,A6,'Table 3 - shake'!$B$4:$B$505)+SUMIF('Обяд'!$A$4:$A$505,A6,'Обяд'!$B$4:$B$505)+SUMIF('Вечеря'!$A$4:$A$505,A6,'Вечеря'!$B$4:$B$505)) -> 10 | C6: 452 | D6: 32 | E6: 3.1 | F6: 4.3 | G6: 1 | H6: 21 | I6: 32 | J6: 19.5 | K6: 5.5 | L6: =IF(B6="","",B6*C6/100) -> 45.2 | M6: =IF(B6="","",B6*D6/100) -> 3.2 | N6: =IF(B6="","",B6*E6/100) -> 0.31 | O6: =IF(B6="","",B6*F6/100) -> 0.43 | P6: =IF(B6="","",B6*G6/100) -> 0.1 | Q6: =IF(B6="","",B6*H6/100) -> 2.1 | R6: =IF(B6="","",B6*I6/100) -> 3.2 | S6: =IF(B6="","",B6*J6/100) -> 1.95 | T6: =IF(B6="","",B6*K6/100) -> 0.55
A7: Biscuit whey | B7: =IF(A7="","",SUMIF('Table 3 - shake'!$A$4:$A$505,A7,'Table 3 - shake'!$B$4:$B$505)+SUMIF('Обяд'!$A$4:$A$505,A7,'Обяд'!$B$4:$B$505)+SUMIF('Вечеря'!$A$4:$A$505,A7,'Вечеря'!$B$4:$B$505)) -> 20 | C7: 399 | D7: 6 | E7: 2.5 | F7: 13 | G7: 6.5 | H7: 73 | I7: 0 | J7: 0 | K7: 0 | L7: =IF(B7="","",B7*C7/100) -> 79.8 | M7: =IF(B7="","",B7*D7/100) -> 1.2 | N7: =IF(B7="","",B7*E7/100) -> 0.5 | O7: =IF(B7="","",B7*F7/100) -> 2.6 | P7: =IF(B7="","",B7*G7/100) -> 1.3 | Q7: =IF(B7="","",B7*H7/100) -> 14.6 | R7: =IF(B7="","",B7*I7/100) -> 0 | S7: =IF(B7="","",B7*J7/100) -> 0 | T7: =IF(B7="","",B7*K7/100) -> 0
A8: Heinz ketchup no sugar | B8: =IF(A8="","",SUMIF('Table 3 - shake'!$A$4:$A$505,A8,'Table 3 - shake'!$B$4:$B$505)+SUMIF('Обяд'!$A$4:$A$505,A8,'Обяд'!$B$4:$B$505)+SUMIF('Вечеря'!$A$4:$A$505,A8,'Вечеря'!$B$4:$B$505)) -> 25 | C8: 40 | D8: 0.1 | E8: 0 | F8: 5.9 | G8: 5 | H8: 1.6 | I8: 0 | J8: 0 | K8: 0 | L8: =IF(B8="","",B8*C8/100) -> 10 | M8: =IF(B8="","",B8*D8/100) -> 0.025 | N8: =IF(B8="","",B8*E8/100) -> 0 | O8: =IF(B8="","",B8*F8/100) -> 1.475 | P8: =IF(B8="","",B8*G8/100) -> 1.25 | Q8: =IF(B8="","",B8*H8/100) -> 0.4 | R8: =IF(B8="","",B8*I8/100) -> 0 | S8: =IF(B8="","",B8*J8/100) -> 0 | T8: =IF(B8="","",B8*K8/100) -> 0
A9: Heinz mustard | B9: =IF(A9="","",SUMIF('Table 3 - shake'!$A$4:$A$505,A9,'Table 3 - shake'!$B$4:$B$505)+SUMIF('Обяд'!$A$4:$A$505,A9,'Обяд'!$B$4:$B$505)+SUMIF('Вечеря'!$A$4:$A$505,A9,'Вечеря'!$B$4:$B$505)) -> 10 | C9: 120 | D9: 5.2 | E9: 0.3 | F9: 9.4 | G9: 5.3 | H9: 5.6 | I9: 0 | J9: 0 | K9: 0 | L9: =IF(B9="","",B9*C9/100) -> 12 | M9: =IF(B9="","",B9*D9/100) -> 0.52 | N9: =IF(B9="","",B9*E9/100) -> 0.03 | O9: =IF(B9="","",B9*F9/100) -> 0.94 | P9: =IF(B9="","",B9*G9/100) -> 0.53 | Q9: =IF(B9="","",B9*H9/100) -> 0.56 | R9: =IF(B9="","",B9*I9/100) -> 0 | S9: =IF(B9="","",B9*J9/100) -> 0 | T9: =IF(B9="","",B9*K9/100) -> 0
A10: Pink Skyr | B10: =IF(A10="","",SUMIF('Table 3 - shake'!$A$4:$A$505,A10,'Table 3 - shake'!$B$4:$B$505)+SUMIF('Обяд'!$A$4:$A$505,A10,'Обяд'!$B$4:$B$505)+SUMIF('Вечеря'!$A$4:$A$505,A10,'Вечеря'!$B$4:$B$505)) -> 100 | C10: 52 | D10: 0.2 | E10: 0.1 | F10: 3.6 | G10: 3.6 | H10: 8.5 | I10: 0 | J10: 0 | K10: 0 | L10: =IF(B10="","",B10*C10/100) -> 52 | M10: =IF(B10="","",B10*D10/100) -> 0.2 | N10: =IF(B10="","",B10*E10/100) -> 0.1 | O10: =IF(B10="","",B10*F10/100) -> 3.6 | P10: =IF(B10="","",B10*G10/100) -> 3.6 | Q10: =IF(B10="","",B10*H10/100) -> 8.5 | R10: =IF(B10="","",B10*I10/100) -> 0 | S10: =IF(B10="","",B10*J10/100) -> 0 | T10: =IF(B10="","",B10*K10/100) -> 0
A11: Beef mincemeat cooked | B11: =IF(A11="","",SUMIF('Table 3 - shake'!$A$4:$A$505,A11,'Table 3 - shake'!$B$4:$B$505)+SUMIF('Обяд'!$A$4:$A$505,A11,'Обяд'!$B$4:$B$505)+SUMIF('Вечеря'!$A$4:$A$505,A11,'Вечеря'!$B$4:$B$505)) -> 200 | C11: 214 | D11: 11.1 | E11: 4.4 | F11: 0 | G11: 0 | H11: 26.6 | I11: 0 | J11: 0 | K11: 0 | L11: =IF(B11="","",B11*C11/100) -> 428 | M11: =IF(B11="","",B11*D11/100) -> 22.2 | N11: =IF(B11="","",B11*E11/100) -> 8.8 | O11: =IF(B11="","",B11*F11/100) -> 0 | P11: =IF(B11="","",B11*G11/100) -> 0 | Q11: =IF(B11="","",B11*H11/100) -> 53.2 | R11: =IF(B11="","",B11*I11/100) -> 0 | S11: =IF(B11="","",B11*J11/100) -> 0 | T11: =IF(B11="","",B11*K11/100) -> 0
A12: Chicken fillet cooked | B12: =IF(A12="","",SUMIF('Table 3 - shake'!$A$4:$A$505,A12,'Table 3 - shake'!$B$4:$B$505)+SUMIF('Обяд'!$A$4:$A$505,A12,'Обяд'!$B$4:$B$505)+SUMIF('Вечеря'!$A$4:$A$505,A12,'Вечеря'!$B$4:$B$505)) -> 160 | C12: 165 | D12: 3.57 | E12: 1.01 | F12: 0 | G12: 0 | H12: 31.02 | I12: 0 | J12: 0 | K12: 0 | L12: =IF(B12="","",B12*C12/100) -> 264 | M12: =IF(B12="","",B12*D12/100) -> 5.712 | N12: =IF(B12="","",B12*E12/100) -> 1.616 | O12: =IF(B12="","",B12*F12/100) -> 0 | P12: =IF(B12="","",B12*G12/100) -> 0 | Q12: =IF(B12="","",B12*H12/100) -> 49.632 | R12: =IF(B12="","",B12*I12/100) -> 0 | S12: =IF(B12="","",B12*J12/100) -> 0 | T12: =IF(B12="","",B12*K12/100) -> 0
A13: Kiwi | B13: =IF(A13="","",SUMIF('Table 3 - shake'!$A$4:$A$505,A13,'Table 3 - shake'!$B$4:$B$505)+SUMIF('Обяд'!$A$4:$A$505,A13,'Обяд'!$B$4:$B$505)+SUMIF('Вечеря'!$A$4:$A$505,A13,'Вечеря'!$B$4:$B$505)) -> 0 | C13: 61 | D13: 0.52 | E13: 0.03 | F13: 14.66 | G13: 8.99 | H13: 1.14 | I13: 3 | J13: 0 | K13: 0 | L13: =IF(B13="","",B13*C13/100) -> 0 | M13: =IF(B13="","",B13*D13/100) -> 0 | N13: =IF(B13="","",B13*E13/100) -> 0 | O13: =IF(B13="","",B13*F13/100) -> 0 | P13: =IF(B13="","",B13*G13/100) -> 0 | Q13: =IF(B13="","",B13*H13/100) -> 0 | R13: =IF(B13="","",B13*I13/100) -> 0 | S13: =IF(B13="","",B13*J13/100) -> 0 | T13: =IF(B13="","",B13*K13/100) -> 0
A14: Banana | B14: =IF(A14="","",SUMIF('Table 3 - shake'!$A$4:$A$505,A14,'Table 3 - shake'!$B$4:$B$505)+SUMIF('Обяд'!$A$4:$A$505,A14,'Обяд'!$B$4:$B$505)+SUMIF('Вечеря'!$A$4:$A$505,A14,'Вечеря'!$B$4:$B$505)) -> 56 | C14: 89 | D14: 0.33 | E14: 0.11 | F14: 22.84 | G14: 12.23 | H14: 1.09 | I14: 2.6 | J14: 0 | K14: 0 | L14: =IF(B14="","",B14*C14/100) -> 49.84 | M14: =IF(B14="","",B14*D14/100) -> 0.1848 | N14: =IF(B14="","",B14*E14/100) -> 0.0616 | O14: =IF(B14="","",B14*F14/100) -> 12.7904 | P14: =IF(B14="","",B14*G14/100) -> 6.8488 | Q14: =IF(B14="","",B14*H14/100) -> 0.6104 | R14: =IF(B14="","",B14*I14/100) -> 1.456 | S14: =IF(B14="","",B14*J14/100) -> 0 | T14: =IF(B14="","",B14*K14/100) -> 0
A15: Green apple | B15: =IF(A15="","",SUMIF('Table 3 - shake'!$A$4:$A$505,A15,'Table 3 - shake'!$B$4:$B$505)+SUMIF('Обяд'!$A$4:$A$505,A15,'Обяд'!$B$4:$B$505)+SUMIF('Вечеря'!$A$4:$A$505,A15,'Вечеря'!$B$4:$B$505)) -> 0 | C15: 52 | D15: 0.17 | E15: 0.03 | F15: 13.81 | G15: 10.39 | H15: 0.26 | I15: 2.4 | J15: 0 | K15: 0 | L15: =IF(B15="","",B15*C15/100) -> 0 | M15: =IF(B15="","",B15*D15/100) -> 0 | N15: =IF(B15="","",B15*E15/100) -> 0 | O15: =IF(B15="","",B15*F15/100) -> 0 | P15: =IF(B15="","",B15*G15/100) -> 0 | Q15: =IF(B15="","",B15*H15/100) -> 0 | R15: =IF(B15="","",B15*I15/100) -> 0 | S15: =IF(B15="","",B15*J15/100) -> 0 | T15: =IF(B15="","",B15*K15/100) -> 0
A16: Strawberries | B16: =IF(A16="","",SUMIF('Table 3 - shake'!$A$4:$A$505,A16,'Table 3 - shake'!$B$4:$B$505)+SUMIF('Обяд'!$A$4:$A$505,A16,'Обяд'!$B$4:$B$505)+SUMIF('Вечеря'!$A$4:$A$505,A16,'Вечеря'!$B$4:$B$505)) -> 0 | C16: 32 | D16: 0.3 | E16: 0.02 | F16: 7.68 | G16: 4.89 | H16: 0.67 | I16: 2 | J16: 0 | K16: 0 | L16: =IF(B16="","",B16*C16/100) -> 0 | M16: =IF(B16="","",B16*D16/100) -> 0 | N16: =IF(B16="","",B16*E16/100) -> 0 | O16: =IF(B16="","",B16*F16/100) -> 0 | P16: =IF(B16="","",B16*G16/100) -> 0 | Q16: =IF(B16="","",B16*H16/100) -> 0 | R16: =IF(B16="","",B16*I16/100) -> 0 | S16: =IF(B16="","",B16*J16/100) -> 0 | T16: =IF(B16="","",B16*K16/100) -> 0
A17: Raspberries | B17: =IF(A17="","",SUMIF('Table 3 - shake'!$A$4:$A$505,A17,'Table 3 - shake'!$B$4:$B$505)+SUMIF('Обяд'!$A$4:$A$505,A17,'Обяд'!$B$4:$B$505)+SUMIF('Вечеря'!$A$4:$A$505,A17,'Вечеря'!$B$4:$B$505)) -> 50 | C17: 52 | D17: 0.65 | E17: 0.02 | F17: 11.94 | G17: 4.42 | H17: 1.2 | I17: 6.5 | J17: 0 | K17: 0 | L17: =IF(B17="","",B17*C17/100) -> 26 | M17: =IF(B17="","",B17*D17/100) -> 0.325 | N17: =IF(B17="","",B17*E17/100) -> 0.01 | O17: =IF(B17="","",B17*F17/100) -> 5.97 | P17: =IF(B17="","",B17*G17/100) -> 2.21 | Q17: =IF(B17="","",B17*H17/100) -> 0.6 | R17: =IF(B17="","",B17*I17/100) -> 3.25 | S17: =IF(B17="","",B17*J17/100) -> 0 | T17: =IF(B17="","",B17*K17/100) -> 0
... A31: White rice cooked | B31: =IF(A31="","",SUMIF('Table 3 - shake'!$A$4:$A$505,A31,'Table 3 - shake'!$B$4:$B$505)+SUMIF('Обяд'!$A$4:$A$505,A31,'Обяд'!$B$4:$B$505)+SUMIF('Вечеря'!$A$4:$A$505,A31,'Вечеря'!$B$4:$B$505)) -> 0 | C31: 130 | D31: 0.28 | E31: 0.076 | F31: 28.17 | G31: 0.05 | H31: 2.69 | I31: 0.4 | J31: 0.009 | K31: 0.063 | L31: =IF(B31="","",B31*C31/100) -> 0 | M31: =IF(B31="","",B31*D31/100) -> 0 | N31: =IF(B31="","",B31*E31/100) -> 0 | O31: =IF(B31="","",B31*F31/100) -> 0 | P31: =IF(B31="","",B31*G31/100) -> 0 | Q31: =IF(B31="","",B31*H31/100) -> 0 | R31: =IF(B31="","",B31*I31/100) -> 0 | S31: =IF(B31="","",B31*J31/100) -> 0 | T31: =IF(B31="","",B31*K31/100) -> 0
A32: =Cocoa!$A$1 -> Cocoa Ice Cream | B32: =IF(A32="","",SUMIF('Table 3 - shake'!$A$4:$A$505,A32,'Table 3 - shake'!$B$4:$B$505)+SUMIF('Обяд'!$A$4:$A$505,A32,'Обяд'!$B$4:$B$505)+SUMIF('Вечеря'!$A$4:$A$505,A32,'Вечеря'!$B$4:$B$505)) -> 0 | C32: =IF(OR(Cocoa!$B$2=0,Cocoa!$C$2=""),"",Cocoa!$C$2/Cocoa!$B$2*100) -> 54.71319 | D32: =IF(OR(Cocoa!$B$2=0,Cocoa!$D$2=""),"",Cocoa!$D$2/Cocoa!$B$2*100) -> 1.845092 | E32: =IF(OR(Cocoa!$B$2=0,Cocoa!$E$2=""),"",Cocoa!$E$2/Cocoa!$B$2*100) -> 1.265184 | F32: =IF(OR(Cocoa!$B$2=0,Cocoa!$F$2=""),"",Cocoa!$F$2/Cocoa!$B$2*100) -> 3.0184049 | G32: =IF(OR(Cocoa!$B$2=0,Cocoa!$G$2=""),"",Cocoa!$G$2/Cocoa!$B$2*100) -> 2.297546 | H32: =IF(OR(Cocoa!$B$2=0,Cocoa!$H$2=""),"",Cocoa!$H$2/Cocoa!$B$2*100) -> 5.851227 | I32: =IF(OR(Cocoa!$B$2=0,Cocoa!$I$2=""),"",Cocoa!$I$2/Cocoa!$B$2*100) -> 1.1383436 | J32: =IF(OR(Cocoa!$B$2=0,Cocoa!$J$2=""),"",Cocoa!$J$2/Cocoa!$B$2*100) -> 0 | K32: =IF(OR(Cocoa!$B$2=0,Cocoa!$K$2=""),"",Cocoa!$K$2/Cocoa!$B$2*100) -> 0 | L32: =IF(OR(B$32="",B$32=0),0,B$32*C32/100) -> 0 | M32: =IF(OR($B$32="",$B$32=0),0,$B$32*D32/100) -> 0 | N32: =IF(OR($B$32="",$B$32=0),0,$B$32*E32/100) -> 0 | O32: =IF(OR($B$32="",$B$32=0),0,$B$32*F32/100) -> 0 | P32: =IF(OR($B$32="",$B$32=0),0,$B$32*G32/100) -> 0 | Q32: =IF(OR($B$32="",$B$32=0),0,$B$32*H32/100) -> 0 | R32: =IF(OR($B$32="",$B$32=0),0,$B$32*I32/100) -> 0 | S32: =IF(OR($B$32="",$B$32=0),0,$B$32*J32/100) -> 0 | T32: =IF(OR($B$32="",$B$32=0),0,$B$32*K32/100) -> 0
A33: ='vanilla ice cream'!$A$1 -> Vanilla ice cream | B33: =IF(A33="","",SUMIF('Table 3 - shake'!$A$4:$A$505,A33,'Table 3 - shake'!$B$4:$B$505)+SUMIF('Обяд'!$A$4:$A$505,A33,'Обяд'!$B$4:$B$505)+SUMIF('Вечеря'!$A$4:$A$505,A33,'Вечеря'!$B$4:$B$505)) -> 0 | C33: =IF(OR('vanilla ice cream'!$B$2=0,'vanilla ice cream'!$C$2=""),"",'vanilla ice cream'!$C$2/'vanilla ice cream'!$B$2*100) | D33: =IF(OR('vanilla ice cream'!$B$2=0,'vanilla ice cream'!$D$2=""),"",'vanilla ice cream'!$D$2/'vanilla ice cream'!$B$2*100) | E33: =IF(OR('vanilla ice cream'!$B$2=0,'vanilla ice cream'!$E$2=""),"",'vanilla ice cream'!$E$2/'vanilla ice cream'!$B$2*100) | F33: =IF(OR('vanilla ice cream'!$B$2=0,'vanilla ice cream'!$F$2=""),"",'vanilla ice cream'!$F$2/'vanilla ice cream'!$B$2*100) | G33: =IF(OR('vanilla ice cream'!$B$2=0,'vanilla ice cream'!$G$2=""),"",'vanilla ice cream'!$G$2/'vanilla ice cream'!$B$2*100) | H33: =IF(OR('vanilla ice cream'!$B$2=0,'vanilla ice cream'!$H$2=""),"",'vanilla ice cream'!$H$2/'vanilla ice cream'!$B$2*100) | I33: =IF(OR('vanilla ice cream'!$B$2=0,'vanilla ice cream'!$I$2=""),"",'vanilla ice cream'!$I$2/'vanilla ice cream'!$B$2*100) | J33: =IF(OR('vanilla ice cream'!$B$2=0,'vanilla ice cream'!$J$2=""),"",'vanilla ice cream'!$J$2/'vanilla ice cream'!$B$2*100) | K33: =IF(OR('vanilla ice cream'!$B$2=0,'vanilla ice cream'!$K$2=""),"",'vanilla ice cream'!$K$2/'vanilla ice cream'!$B$2*100) | L33: =IF(OR(B$33="",B$33=0),0,B$33*C33/100) -> 0 | M33: =IF(OR(C$33="",C$33=0),0,C$33*D33/100) -> 0 | N33: =IF(OR(D$33="",D$33=0),0,D$33*E33/100) -> 0 | O33: =IF(OR(E$33="",E$33=0),0,E$33*F33/100) -> 0 | P33: =IF(OR(F$33="",F$33=0),0,F$33*G33/100) -> 0 | Q33: =IF(OR(G$33="",G$33=0),0,G$33*H33/100) -> 0 | R33: =IF(OR(H$33="",H$33=0),0,H$33*I33/100) -> 0 | S33: =IF(OR(I$33="",I$33=0),0,I$33*J33/100) -> 0 | T33: =IF(OR(J$33="",J$33=0),0,J$33*K33/100) -> 0
A34: Jobo Choko Cookies | B34: =IF(A34="","",SUMIF('Table 3 - shake'!$A$4:$A$505,A34,'Table 3 - shake'!$B$4:$B$505)+SUMIF('Обяд'!$A$4:$A$505,A34,'Обяд'!$B$4:$B$505)+SUMIF('Вечеря'!$A$4:$A$505,A34,'Вечеря'!$B$4:$B$505)) -> 100 | C34: 340 | G34: 30 | L34: =IF(B34="","",B34*C34/100) -> 340 | M34: =IF(B34="","",B34*D34/100) -> 0 | N34: =IF(B34="","",B34*E34/100) -> 0 | O34: =IF(B34="","",B34*F34/100) -> 0 | P34: =IF(B34="","",B34*G34/100) -> 30 | Q34: =IF(B34="","",B34*H34/100) -> 0 | R34: =IF(B34="","",B34*I34/100) -> 0 | S34: =IF(B34="","",B34*J34/100) -> 0 | T34: =IF(B34="","",B34*K34/100) -> 0
B35: =IF(A35="","",SUMIF('Table 3 - shake'!$A$4:$A$505,A35,'Table 3 - shake'!$B$4:$B$505)+SUMIF('Обяд'!$A$4:$A$505,A35,'Обяд'!$B$4:$B$505)+SUMIF('Вечеря'!$A$4:$A$505,A35,'Вечеря'!$B$4:$B$505)) | L35: =IF(B35="","",B35*C35/100) | M35: =IF(B35="","",B35*D35/100) | N35: =IF(B35="","",B35*E35/100) | O35: =IF(B35="","",B35*F35/100) | P35: =IF(B35="","",B35*G35/100) | Q35: =IF(B35="","",B35*H35/100) | R35: =IF(B35="","",B35*I35/100) | S35: =IF(B35="","",B35*J35/100) | T35: =IF(B35="","",B35*K35/100)
B36: =IF(A36="","",SUMIF('Table 3 - shake'!$A$4:$A$505,A36,'Table 3 - shake'!$B$4:$B$505)+SUMIF('Обяд'!$A$4:$A$505,A36,'Обяд'!$B$4:$B$505)+SUMIF('Вечеря'!$A$4:$A$505,A36,'Вечеря'!$B$4:$B$505)) | L36: =IF(B36="","",B36*C36/100) | M36: =IF(B36="","",B36*D36/100) | N36: =IF(B36="","",B36*E36/100) | O36: =IF(B36="","",B36*F36/100) | P36: =IF(B36="","",B36*G36/100) | Q36: =IF(B36="","",B36*H36/100) | R36: =IF(B36="","",B36*I36/100) | S36: =IF(B36="","",B36*J36/100) | T36: =IF(B36="","",B36*K36/100)
B37: =IF(A37="","",SUMIF('Table 3 - shake'!$A$4:$A$505,A37,'Table 3 - shake'!$B$4:$B$505)+SUMIF('Обяд'!$A$4:$A$505,A37,'Обяд'!$B$4:$B$505)+SUMIF('Вечеря'!$A$4:$A$505,A37,'Вечеря'!$B$4:$B$505)) | L37: =IF(B37="","",B37*C37/100) | M37: =IF(B37="","",B37*D37/100) | N37: =IF(B37="","",B37*E37/100) | O37: =IF(B37="","",B37*F37/100) | P37: =IF(B37="","",B37*G37/100) | Q37: =IF(B37="","",B37*H37/100) | R37: =IF(B37="","",B37*I37/100) | S37: =IF(B37="","",B37*J37/100) | T37: =IF(B37="","",B37*K37/100)
B38: =IF(A38="","",SUMIF('Table 3 - shake'!$A$4:$A$505,A38,'Table 3 - shake'!$B$4:$B$505)+SUMIF('Обяд'!$A$4:$A$505,A38,'Обяд'!$B$4:$B$505)+SUMIF('Вечеря'!$A$4:$A$505,A38,'Вечеря'!$B$4:$B$505)) | L38: =IF(B38="","",B38*C38/100) | M38: =IF(B38="","",B38*D38/100) | N38: =IF(B38="","",B38*E38/100) | O38: =IF(B38="","",B38*F38/100) | P38: =IF(B38="","",B38*G38/100) | Q38: =IF(B38="","",B38*H38/100) | R38: =IF(B38="","",B38*I38/100) | S38: =IF(B38="","",B38*J38/100) | T38: =IF(B38="","",B38*K38/100)
B39: =IF(A39="","",SUMIF('Table 3 - shake'!$A$4:$A$505,A39,'Table 3 - shake'!$B$4:$B$505)+SUMIF('Обяд'!$A$4:$A$505,A39,'Обяд'!$B$4:$B$505)+SUMIF('Вечеря'!$A$4:$A$505,A39,'Вечеря'!$B$4:$B$505)) | L39: =IF(B39="","",B39*C39/100) | M39: =IF(B39="","",B39*D39/100) | N39: =IF(B39="","",B39*E39/100) | O39: =IF(B39="","",B39*F39/100) | P39: =IF(B39="","",B39*G39/100) | Q39: =IF(B39="","",B39*H39/100) | R39: =IF(B39="","",B39*I39/100) | S39: =IF(B39="","",B39*J39/100) | T39: =IF(B39="","",B39*K39/100)
B40: =IF(A40="","",SUMIF('Table 3 - shake'!$A$4:$A$505,A40,'Table 3 - shake'!$B$4:$B$505)+SUMIF('Обяд'!$A$4:$A$505,A40,'Обяд'!$B$4:$B$505)+SUMIF('Вечеря'!$A$4:$A$505,A40,'Вечеря'!$B$4:$B$505)) | L40: =IF(B40="","",B40*C40/100) | M40: =IF(B40="","",B40*D40/100) | N40: =IF(B40="","",B40*E40/100) | O40: =IF(B40="","",B40*F40/100) | P40: =IF(B40="","",B40*G40/100) | Q40: =IF(B40="","",B40*H40/100) | R40: =IF(B40="","",B40*I40/100) | S40: =IF(B40="","",B40*J40/100) | T40: =IF(B40="","",B40*K40/100)
B41: =IF(A41="","",SUMIF('Table 3 - shake'!$A$4:$A$505,A41,'Table 3 - shake'!$B$4:$B$505)+SUMIF('Обяд'!$A$4:$A$505,A41,'Обяд'!$B$4:$B$505)+SUMIF('Вечеря'!$A$4:$A$505,A41,'Вечеря'!$B$4:$B$505)) | L41: =IF(B41="","",B41*C41/100) | M41: =IF(B41="","",B41*D41/100) | N41: =IF(B41="","",B41*E41/100) | O41: =IF(B41="","",B41*F41/100) | P41: =IF(B41="","",B41*G41/100) | Q41: =IF(B41="","",B41*H41/100) | R41: =IF(B41="","",B41*I41/100) | S41: =IF(B41="","",B41*J41/100) | T41: =IF(B41="","",B41*K41/100)
B42: =IF(A42="","",SUMIF('Table 3 - shake'!$A$4:$A$505,A42,'Table 3 - shake'!$B$4:$B$505)+SUMIF('Обяд'!$A$4:$A$505,A42,'Обяд'!$B$4:$B$505)+SUMIF('Вечеря'!$A$4:$A$505,A42,'Вечеря'!$B$4:$B$505)) | L42: =IF(B42="","",B42*C42/100) | M42: =IF(B42="","",B42*D42/100) | N42: =IF(B42="","",B42*E42/100) | O42: =IF(B42="","",B42*F42/100) | P42: =IF(B42="","",B42*G42/100) | Q42: =IF(B42="","",B42*H42/100) | R42: =IF(B42="","",B42*I42/100) | S42: =IF(B42="","",B42*J42/100) | T42: =IF(B42="","",B42*K42/100)
B43: =IF(A43="","",SUMIF('Table 3 - shake'!$A$4:$A$505,A43,'Table 3 - shake'!$B$4:$B$505)+SUMIF('Обяд'!$A$4:$A$505,A43,'Обяд'!$B$4:$B$505)+SUMIF('Вечеря'!$A$4:$A$505,A43,'Вечеря'!$B$4:$B$505)) | L43: =IF(B43="","",B43*C43/100) | M43: =IF(B43="","",B43*D43/100) | N43: =IF(B43="","",B43*E43/100) | O43: =IF(B43="","",B43*F43/100) | P43: =IF(B43="","",B43*G43/100) | Q43: =IF(B43="","",B43*H43/100) | R43: =IF(B43="","",B43*I43/100) | S43: =IF(B43="","",B43*J43/100) | T43: =IF(B43="","",B43*K43/100)
B44: =IF(A44="","",SUMIF('Table 3 - shake'!$A$4:$A$505,A44,'Table 3 - shake'!$B$4:$B$505)+SUMIF('Обяд'!$A$4:$A$505,A44,'Обяд'!$B$4:$B$505)+SUMIF('Вечеря'!$A$4:$A$505,A44,'Вечеря'!$B$4:$B$505)) | L44: =IF(B44="","",B44*C44/100) | M44: =IF(B44="","",B44*D44/100) | N44: =IF(B44="","",B44*E44/100) | O44: =IF(B44="","",B44*F44/100) | P44: =IF(B44="","",B44*G44/100) | Q44: =IF(B44="","",B44*H44/100) | R44: =IF(B44="","",B44*I44/100) | S44: =IF(B44="","",B44*J44/100) | T44: =IF(B44="","",B44*K44/100)
B45: =IF(A45="","",SUMIF('Table 3 - shake'!$A$4:$A$505,A45,'Table 3 - shake'!$B$4:$B$505)+SUMIF('Обяд'!$A$4:$A$505,A45,'Обяд'!$B$4:$B$505)+SUMIF('Вечеря'!$A$4:$A$505,A45,'Вечеря'!$B$4:$B$505)) | L45: =IF(B45="","",B45*C45/100) | M45: =IF(B45="","",B45*D45/100) | N45: =IF(B45="","",B45*E45/100) | O45: =IF(B45="","",B45*F45/100) | P45: =IF(B45="","",B45*G45/100) | Q45: =IF(B45="","",B45*H45/100) | R45: =IF(B45="","",B45*I45/100) | S45: =IF(B45="","",B45*J45/100) | T45: =IF(B45="","",B45*K45/100)
B46: =IF(A46="","",SUMIF('Table 3 - shake'!$A$4:$A$505,A46,'Table 3 - shake'!$B$4:$B$505)+SUMIF('Обяд'!$A$4:$A$505,A46,'Обяд'!$B$4:$B$505)+SUMIF('Вечеря'!$A$4:$A$505,A46,'Вечеря'!$B$4:$B$505)) | L46: =IF(B46="","",B46*C46/100) | M46: =IF(B46="","",B46*D46/100) | N46: =IF(B46="","",B46*E46/100) | O46: =IF(B46="","",B46*F46/100) | P46: =IF(B46="","",B46*G46/100) | Q46: =IF(B46="","",B46*H46/100) | R46: =IF(B46="","",B46*I46/100) | S46: =IF(B46="","",B46*J46/100) | T46: =IF(B46="","",B46*K46/100)
... B505: =IF(A505="","",SUMIF('Table 3 - shake'!$A$4:$A$505,A505,'Table 3 - shake'!$B$4:$B$505)+SUMIF('Обяд'!$A$4:$A$505,A505,'Обяд'!$B$4:$B$505)+SUMIF('Вечеря'!$A$4:$A$505,A505,'Вечеря'!$B$4:$B$505)) | L505: =IF(B505="","",B505*C505/100) | M505: =IF(B505="","",B505*D505/100) | N505: =IF(B505="","",B505*E505/100) | O505: =IF(B505="","",B505*F505/100) | P505: =IF(B505="","",B505*G505/100) | Q505: =IF(B505="","",B505*H505/100) | R505: =IF(B505="","",B505*I505/100) | S505: =IF(B505="","",B505*J505/100) | T505: =IF(B505="","",B505*K505/100)

Sheet Cocoa
A1: Cocoa Ice Cream
A2: TOTAL | B2: =SUM(B4:B505) -> 652 | C2: =IF($B$2=0,"",SUM(C4:C505)) -> 356.73 | D2: =IF($B$2=0,"",SUM(D4:D505)) -> 12.03 | E2: =IF($B$2=0,"",SUM(E4:E505)) -> 8.249 | F2: =IF($B$2=0,"",SUM(F4:F505)) -> 19.68 | G2: =IF($B$2=0,"",SUM(G4:G505)) -> 14.98 | H2: =IF($B$2=0,"",SUM(H4:H505)) -> 38.15 | I2: =IF($B$2=0,"",SUM(I4:I505)) -> 7.422 | J2: =IF($B$2=0,"",SUM(J4:J505)) -> 0 | K2: =IF($B$2=0,"",SUM(K4:K505)) -> 0
A3: food_name (choose) | B3: grams_eaten | C3: calories | D3: fat | E3: saturated_fat | F3: carbohydrates | G3: sugars | H3: protein | I3: fiber | J3: omega-3 | K3: omega-6
A4: Coconut milk | B4: 300 | C4: {=IF(OR(A4="",B4=""),"",IFERROR(INDEX('All Foods'!$C:$C,MATCH(A4,'All Foods'!$A:$A,0))*B4/100,""))} -> 39 | D4: {=IF(OR(A4="",B4=""),"",IFERROR(INDEX('All Foods'!$D:$D,MATCH(A4,'All Foods'!$A:$A,0))*B4/100,""))} -> 3.6 | E4: {=IF(OR(A4="",B4=""),"",IFERROR(INDEX('All Foods'!$E:$E,MATCH(A4,'All Foods'!$A:$A,0))*B4/100,""))} -> 3.3 | F4: {=IF(OR(A4="",B4=""),"",IFERROR(INDEX('All Foods'!$F:$F,MATCH(A4,'All Foods'!$A:$A,0))*B4/100,""))} -> 0.3 | G4: {=IF(OR(A4="",B4=""),"",IFERROR(INDEX('All Foods'!$G:$G,MATCH(A4,'All Foods'!$A:$A,0))*B4/100,""))} -> 0.3 | H4: {=IF(OR(A4="",B4=""),"",IFERROR(INDEX('All Foods'!$H:$H,MATCH(A4,'All Foods'!$A:$A,0))*B4/100,""))} -> 0.3 | I4: {=IF(OR(A4="",B4=""),"",IFERROR(INDEX('All Foods'!$I:$I,MATCH(A4,'All Foods'!$A:$A,0))*B4/100,""))} -> 2.1 | J4: {=IF(OR(A4="",B4=""),"",IFERROR(INDEX('All Foods'!$J:$J,MATCH(A4,'All Foods'!$A:$A,0))*B4/100,""))} -> 0 | K4: {=IF(OR(A4="",B4=""),"",IFERROR(INDEX('All Foods'!$K:$K,MATCH(A4,'All Foods'!$A:$A,0))*B4/100,""))} -> 0
A5: Verea yellow low fat milk | B5: 300 | C5: {=IF(OR(A5="",B5=""),"",IFERROR(INDEX('All Foods'!$C:$C,MATCH(A5,'All Foods'!$A:$A,0))*B5/100,""))} -> 125.7 | D5: {=IF(OR(A5="",B5=""),"",IFERROR(INDEX('All Foods'!$D:$D,MATCH(A5,'All Foods'!$A:$A,0))*B5/100,""))} -> 4.5 | E5: {=IF(OR(A5="",B5=""),"",IFERROR(INDEX('All Foods'!$E:$E,MATCH(A5,'All Foods'!$A:$A,0))*B5/100,""))} -> 2.91 | F5: {=IF(OR(A5="",B5=""),"",IFERROR(INDEX('All Foods'!$F:$F,MATCH(A5,'All Foods'!$A:$A,0))*B5/100,""))} -> 12.3 | G5: {=IF(OR(A5="",B5=""),"",IFERROR(INDEX('All Foods'!$G:$G,MATCH(A5,'All Foods'!$A:$A,0))*B5/100,""))} -> 12.3 | H5: {=IF(OR(A5="",B5=""),"",IFERROR(INDEX('All Foods'!$H:$H,MATCH(A5,'All Foods'!$A:$A,0))*B5/100,""))} -> 9 | I5: {=IF(OR(A5="",B5=""),"",IFERROR(INDEX('All Foods'!$I:$I,MATCH(A5,'All Foods'!$A:$A,0))*B5/100,""))} -> 0 | J5: {=IF(OR(A5="",B5=""),"",IFERROR(INDEX('All Foods'!$J:$J,MATCH(A5,'All Foods'!$A:$A,0))*B5/100,""))} -> 0 | K5: {=IF(OR(A5="",B5=""),"",IFERROR(INDEX('All Foods'!$K:$K,MATCH(A5,'All Foods'!$A:$A,0))*B5/100,""))} -> 0
A6: Cocoa powder | B6: 15 | C6: {=IF(OR(A6="",B6=""),"",IFERROR(INDEX('All Foods'!$C:$C,MATCH(A6,'All Foods'!$A:$A,0))*B6/100,""))} -> 46.2 | D6: {=IF(OR(A6="",B6=""),"",IFERROR(INDEX('All Foods'!$D:$D,MATCH(A6,'All Foods'!$A:$A,0))*B6/100,""))} -> 1.65 | E6: {=IF(OR(A6="",B6=""),"",IFERROR(INDEX('All Foods'!$E:$E,MATCH(A6,'All Foods'!$A:$A,0))*B6/100,""))} -> 0.975 | F6: {=IF(OR(A6="",B6=""),"",IFERROR(INDEX('All Foods'!$F:$F,MATCH(A6,'All Foods'!$A:$A,0))*B6/100,""))} -> 1.8 | G6: {=IF(OR(A6="",B6=""),"",IFERROR(INDEX('All Foods'!$G:$G,MATCH(A6,'All Foods'!$A:$A,0))*B6/100,""))} -> 0 | H6: {=IF(OR(A6="",B6=""),"",IFERROR(INDEX('All Foods'!$H:$H,MATCH(A6,'All Foods'!$A:$A,0))*B6/100,""))} -> 3.15 | I6: {=IF(OR(A6="",B6=""),"",IFERROR(INDEX('All Foods'!$I:$I,MATCH(A6,'All Foods'!$A:$A,0))*B6/100,""))} -> 4.65 | J6: {=IF(OR(A6="",B6=""),"",IFERROR(INDEX('All Foods'!$J:$J,MATCH(A6,'All Foods'!$A:$A,0))*B6/100,""))} -> 0 | K6: {=IF(OR(A6="",B6=""),"",IFERROR(INDEX('All Foods'!$K:$K,MATCH(A6,'All Foods'!$A:$A,0))*B6/100,""))} -> 0
A7: Cacao protein | B7: 30 | C7: {=IF(OR(A7="",B7=""),"",IFERROR(INDEX('All Foods'!$C:$C,MATCH(A7,'All Foods'!$A:$A,0))*B7/100,""))} -> 113.7 | D7: {=IF(OR(A7="",B7=""),"",IFERROR(INDEX('All Foods'!$D:$D,MATCH(A7,'All Foods'!$A:$A,0))*B7/100,""))} -> 1.44 | E7: {=IF(OR(A7="",B7=""),"",IFERROR(INDEX('All Foods'!$E:$E,MATCH(A7,'All Foods'!$A:$A,0))*B7/100,""))} -> 0.84 | F7: {=IF(OR(A7="",B7=""),"",IFERROR(INDEX('All Foods'!$F:$F,MATCH(A7,'All Foods'!$A:$A,0))*B7/100,""))} -> 2.97 | G7: {=IF(OR(A7="",B7=""),"",IFERROR(INDEX('All Foods'!$G:$G,MATCH(A7,'All Foods'!$A:$A,0))*B7/100,""))} -> 1.26 | H7: {=IF(OR(A7="",B7=""),"",IFERROR(INDEX('All Foods'!$H:$H,MATCH(A7,'All Foods'!$A:$A,0))*B7/100,""))} -> 22.2 | I7: {=IF(OR(A7="",B7=""),"",IFERROR(INDEX('All Foods'!$I:$I,MATCH(A7,'All Foods'!$A:$A,0))*B7/100,""))} -> 0 | J7: {=IF(OR(A7="",B7=""),"",IFERROR(INDEX('All Foods'!$J:$J,MATCH(A7,'All Foods'!$A:$A,0))*B7/100,""))} -> 0 | K7: {=IF(OR(A7="",B7=""),"",IFERROR(INDEX('All Foods'!$K:$K,MATCH(A7,'All Foods'!$A:$A,0))*B7/100,""))} -> 0
A8: PB2 powder | B8: 7 | C8: {=IF(OR(A8="",B8=""),"",IFERROR(INDEX('All Foods'!$C:$C,MATCH(A8,'All Foods'!$A:$A,0))*B8/100,""))} -> 32.13 | D8: {=IF(OR(A8="",B8=""),"",IFERROR(INDEX('All Foods'!$D:$D,MATCH(A8,'All Foods'!$A:$A,0))*B8/100,""))} -> 0.84 | E8: {=IF(OR(A8="",B8=""),"",IFERROR(INDEX('All Foods'!$E:$E,MATCH(A8,'All Foods'!$A:$A,0))*B8/100,""))} -> 0.224 | F8: {=IF(OR(A8="",B8=""),"",IFERROR(INDEX('All Foods'!$F:$F,MATCH(A8,'All Foods'!$A:$A,0))*B8/100,""))} -> 2.31 | G8: {=IF(OR(A8="",B8=""),"",IFERROR(INDEX('All Foods'!$G:$G,MATCH(A8,'All Foods'!$A:$A,0))*B8/100,""))} -> 1.12 | H8: {=IF(OR(A8="",B8=""),"",IFERROR(INDEX('All Foods'!$H:$H,MATCH(A8,'All Foods'!$A:$A,0))*B8/100,""))} -> 3.5 | I8: {=IF(OR(A8="",B8=""),"",IFERROR(INDEX('All Foods'!$I:$I,MATCH(A8,'All Foods'!$A:$A,0))*B8/100,""))} -> 0.672 | J8: {=IF(OR(A8="",B8=""),"",IFERROR(INDEX('All Foods'!$J:$J,MATCH(A8,'All Foods'!$A:$A,0))*B8/100,""))} -> 0 | K8: {=IF(OR(A8="",B8=""),"",IFERROR(INDEX('All Foods'!$K:$K,MATCH(A8,'All Foods'!$A:$A,0))*B8/100,""))} -> 0
C9: {=IF(OR(A9="",B9=""),"",IFERROR(INDEX('All Foods'!$C:$C,MATCH(A9,'All Foods'!$A:$A,0))*B9/100,""))} | D9: {=IF(OR(A9="",B9=""),"",IFERROR(INDEX('All Foods'!$D:$D,MATCH(A9,'All Foods'!$A:$A,0))*B9/100,""))} | E9: {=IF(OR(A9="",B9=""),"",IFERROR(INDEX('All Foods'!$E:$E,MATCH(A9,'All Foods'!$A:$A,0))*B9/100,""))} | F9: {=IF(OR(A9="",B9=""),"",IFERROR(INDEX('All Foods'!$F:$F,MATCH(A9,'All Foods'!$A:$A,0))*B9/100,""))} | G9: {=IF(OR(A9="",B9=""),"",IFERROR(INDEX('All Foods'!$G:$G,MATCH(A9,'All Foods'!$A:$A,0))*B9/100,""))} | H9: {=IF(OR(A9="",B9=""),"",IFERROR(INDEX('All Foods'!$H:$H,MATCH(A9,'All Foods'!$A:$A,0))*B9/100,""))} | I9: {=IF(OR(A9="",B9=""),"",IFERROR(INDEX('All Foods'!$I:$I,MATCH(A9,'All Foods'!$A:$A,0))*B9/100,""))} | J9: {=IF(OR(A9="",B9=""),"",IFERROR(INDEX('All Foods'!$J:$J,MATCH(A9,'All Foods'!$A:$A,0))*B9/100,""))} | K9: {=IF(OR(A9="",B9=""),"",IFERROR(INDEX('All Foods'!$K:$K,MATCH(A9,'All Foods'!$A:$A,0))*B9/100,""))}
C10: {=IF(OR(A10="",B10=""),"",IFERROR(INDEX('All Foods'!$C:$C,MATCH(A10,'All Foods'!$A:$A,0))*B10/100,""))} | D10: {=IF(OR(A10="",B10=""),"",IFERROR(INDEX('All Foods'!$D:$D,MATCH(A10,'All Foods'!$A:$A,0))*B10/100,""))} | E10: {=IF(OR(A10="",B10=""),"",IFERROR(INDEX('All Foods'!$E:$E,MATCH(A10,'All Foods'!$A:$A,0))*B10/100,""))} | F10: {=IF(OR(A10="",B10=""),"",IFERROR(INDEX('All Foods'!$F:$F,MATCH(A10,'All Foods'!$A:$A,0))*B10/100,""))} | G10: {=IF(OR(A10="",B10=""),"",IFERROR(INDEX('All Foods'!$G:$G,MATCH(A10,'All Foods'!$A:$A,0))*B10/100,""))} | H10: {=IF(OR(A10="",B10=""),"",IFERROR(INDEX('All Foods'!$H:$H,MATCH(A10,'All Foods'!$A:$A,0))*B10/100,""))} | I10: {=IF(OR(A10="",B10=""),"",IFERROR(INDEX('All Foods'!$I:$I,MATCH(A10,'All Foods'!$A:$A,0))*B10/100,""))} | J10: {=IF(OR(A10="",B10=""),"",IFERROR(INDEX('All Foods'!$J:$J,MATCH(A10,'All Foods'!$A:$A,0))*B10/100,""))} | K10: {=IF(OR(A10="",B10=""),"",IFERROR(INDEX('All Foods'!$K:$K,MATCH(A10,'All Foods'!$A:$A,0))*B10/100,""))}
C11: {=IF(OR(A11="",B11=""),"",IFERROR(INDEX('All Foods'!$C:$C,MATCH(A11,'All Foods'!$A:$A,0))*B11/100,""))} | D11: {=IF(OR(A11="",B11=""),"",IFERROR(INDEX('All Foods'!$D:$D,MATCH(A11,'All Foods'!$A:$A,0))*B11/100,""))} | E11: {=IF(OR(A11="",B11=""),"",IFERROR(INDEX('All Foods'!$E:$E,MATCH(A11,'All Foods'!$A:$A,0))*B11/100,""))} | F11: {=IF(OR(A11="",B11=""),"",IFERROR(INDEX('All Foods'!$F:$F,MATCH(A11,'All Foods'!$A:$A,0))*B11/100,""))} | G11: {=IF(OR(A11="",B11=""),"",IFERROR(INDEX('All Foods'!$G:$G,MATCH(A11,'All Foods'!$A:$A,0))*B11/100,""))} | H11: {=IF(OR(A11="",B11=""),"",IFERROR(INDEX('All Foods'!$H:$H,MATCH(A11,'All Foods'!$A:$A,0))*B11/100,""))} | I11: {=IF(OR(A11="",B11=""),"",IFERROR(INDEX('All Foods'!$I:$I,MATCH(A11,'All Foods'!$A:$A,0))*B11/100,""))} | J11: {=IF(OR(A11="",B11=""),"",IFERROR(INDEX('All Foods'!$J:$J,MATCH(A11,'All Foods'!$A:$A,0))*B11/100,""))} | K11: {=IF(OR(A11="",B11=""),"",IFERROR(INDEX('All Foods'!$K:$K,MATCH(A11,'All Foods'!$A:$A,0))*B11/100,""))}
C12: {=IF(OR(A12="",B12=""),"",IFERROR(INDEX('All Foods'!$C:$C,MATCH(A12,'All Foods'!$A:$A,0))*B12/100,""))} | D12: {=IF(OR(A12="",B12=""),"",IFERROR(INDEX('All Foods'!$D:$D,MATCH(A12,'All Foods'!$A:$A,0))*B12/100,""))} | E12: {=IF(OR(A12="",B12=""),"",IFERROR(INDEX('All Foods'!$E:$E,MATCH(A12,'All Foods'!$A:$A,0))*B12/100,""))} | F12: {=IF(OR(A12="",B12=""),"",IFERROR(INDEX('All Foods'!$F:$F,MATCH(A12,'All Foods'!$A:$A,0))*B12/100,""))} | G12: {=IF(OR(A12="",B12=""),"",IFERROR(INDEX('All Foods'!$G:$G,MATCH(A12,'All Foods'!$A:$A,0))*B12/100,""))} | H12: {=IF(OR(A12="",B12=""),"",IFERROR(INDEX('All Foods'!$H:$H,MATCH(A12,'All Foods'!$A:$A,0))*B12/100,""))} | I12: {=IF(OR(A12="",B12=""),"",IFERROR(INDEX('All Foods'!$I:$I,MATCH(A12,'All Foods'!$A:$A,0))*B12/100,""))} | J12: {=IF(OR(A12="",B12=""),"",IFERROR(INDEX('All Foods'!$J:$J,MATCH(A12,'All Foods'!$A:$A,0))*B12/100,""))} | K12: {=IF(OR(A12="",B12=""),"",IFERROR(INDEX('All Foods'!$K:$K,MATCH(A12,'All Foods'!$A:$A,0))*B12/100,""))}
C13: {=IF(OR(A13="",B13=""),"",IFERROR(INDEX('All Foods'!$C:$C,MATCH(A13,'All Foods'!$A:$A,0))*B13/100,""))} | D13: {=IF(OR(A13="",B13=""),"",IFERROR(INDEX('All Foods'!$D:$D,MATCH(A13,'All Foods'!$A:$A,0))*B13/100,""))} | E13: {=IF(OR(A13="",B13=""),"",IFERROR(INDEX('All Foods'!$E:$E,MATCH(A13,'All Foods'!$A:$A,0))*B13/100,""))} | F13: {=IF(OR(A13="",B13=""),"",IFERROR(INDEX('All Foods'!$F:$F,MATCH(A13,'All Foods'!$A:$A,0))*B13/100,""))} | G13: {=IF(OR(A13="",B13=""),"",IFERROR(INDEX('All Foods'!$G:$G,MATCH(A13,'All Foods'!$A:$A,0))*B13/100,""))} | H13: {=IF(OR(A13="",B13=""),"",IFERROR(INDEX('All Foods'!$H:$H,MATCH(A13,'All Foods'!$A:$A,0))*B13/100,""))} | I13: {=IF(OR(A13="",B13=""),"",IFERROR(INDEX('All Foods'!$I:$I,MATCH(A13,'All Foods'!$A:$A,0))*B13/100,""))} | J13: {=IF(OR(A13="",B13=""),"",IFERROR(INDEX('All Foods'!$J:$J,MATCH(A13,'All Foods'!$A:$A,0))*B13/100,""))} | K13: {=IF(OR(A13="",B13=""),"",IFERROR(INDEX('All Foods'!$K:$K,MATCH(A13,'All Foods'!$A:$A,0))*B13/100,""))}
C14: {=IF(OR(A14="",B14=""),"",IFERROR(INDEX('All Foods'!$C:$C,MATCH(A14,'All Foods'!$A:$A,0))*B14/100,""))} | D14: {=IF(OR(A14="",B14=""),"",IFERROR(INDEX('All Foods'!$D:$D,MATCH(A14,'All Foods'!$A:$A,0))*B14/100,""))} | E14: {=IF(OR(A14="",B14=""),"",IFERROR(INDEX('All Foods'!$E:$E,MATCH(A14,'All Foods'!$A:$A,0))*B14/100,""))} | F14: {=IF(OR(A14="",B14=""),"",IFERROR(INDEX('All Foods'!$F:$F,MATCH(A14,'All Foods'!$A:$A,0))*B14/100,""))} | G14: {=IF(OR(A14="",B14=""),"",IFERROR(INDEX('All Foods'!$G:$G,MATCH(A14,'All Foods'!$A:$A,0))*B14/100,""))} | H14: {=IF(OR(A14="",B14=""),"",IFERROR(INDEX('All Foods'!$H:$H,MATCH(A14,'All Foods'!$A:$A,0))*B14/100,""))} | I14: {=IF(OR(A14="",B14=""),"",IFERROR(INDEX('All Foods'!$I:$I,MATCH(A14,'All Foods'!$A:$A,0))*B14/100,""))} | J14: {=IF(OR(A14="",B14=""),"",IFERROR(INDEX('All Foods'!$J:$J,MATCH(A14,'All Foods'!$A:$A,0))*B14/100,""))} | K14: {=IF(OR(A14="",B14=""),"",IFERROR(INDEX('All Foods'!$K:$K,MATCH(A14,'All Foods'!$A:$A,0))*B14/100,""))}
C15: {=IF(OR(A15="",B15=""),"",IFERROR(INDEX('All Foods'!$C:$C,MATCH(A15,'All Foods'!$A:$A,0))*B15/100,""))} | D15: {=IF(OR(A15="",B15=""),"",IFERROR(INDEX('All Foods'!$D:$D,MATCH(A15,'All Foods'!$A:$A,0))*B15/100,""))} | E15: {=IF(OR(A15="",B15=""),"",IFERROR(INDEX('All Foods'!$E:$E,MATCH(A15,'All Foods'!$A:$A,0))*B15/100,""))} | F15: {=IF(OR(A15="",B15=""),"",IFERROR(INDEX('All Foods'!$F:$F,MATCH(A15,'All Foods'!$A:$A,0))*B15/100,""))} | G15: {=IF(OR(A15="",B15=""),"",IFERROR(INDEX('All Foods'!$G:$G,MATCH(A15,'All Foods'!$A:$A,0))*B15/100,""))} | H15: {=IF(OR(A15="",B15=""),"",IFERROR(INDEX('All Foods'!$H:$H,MATCH(A15,'All Foods'!$A:$A,0))*B15/100,""))} | I15: {=IF(OR(A15="",B15=""),"",IFERROR(INDEX('All Foods'!$I:$I,MATCH(A15,'All Foods'!$A:$A,0))*B15/100,""))} | J15: {=IF(OR(A15="",B15=""),"",IFERROR(INDEX('All Foods'!$J:$J,MATCH(A15,'All Foods'!$A:$A,0))*B15/100,""))} | K15: {=IF(OR(A15="",B15=""),"",IFERROR(INDEX('All Foods'!$K:$K,MATCH(A15,'All Foods'!$A:$A,0))*B15/100,""))}
C16: {=IF(OR(A16="",B16=""),"",IFERROR(INDEX('All Foods'!$C:$C,MATCH(A16,'All Foods'!$A:$A,0))*B16/100,""))} | D16: {=IF(OR(A16="",B16=""),"",IFERROR(INDEX('All Foods'!$D:$D,MATCH(A16,'All Foods'!$A:$A,0))*B16/100,""))} | E16: {=IF(OR(A16="",B16=""),"",IFERROR(INDEX('All Foods'!$E:$E,MATCH(A16,'All Foods'!$A:$A,0))*B16/100,""))} | F16: {=IF(OR(A16="",B16=""),"",IFERROR(INDEX('All Foods'!$F:$F,MATCH(A16,'All Foods'!$A:$A,0))*B16/100,""))} | G16: {=IF(OR(A16="",B16=""),"",IFERROR(INDEX('All Foods'!$G:$G,MATCH(A16,'All Foods'!$A:$A,0))*B16/100,""))} | H16: {=IF(OR(A16="",B16=""),"",IFERROR(INDEX('All Foods'!$H:$H,MATCH(A16,'All Foods'!$A:$A,0))*B16/100,""))} | I16: {=IF(OR(A16="",B16=""),"",IFERROR(INDEX('All Foods'!$I:$I,MATCH(A16,'All Foods'!$A:$A,0))*B16/100,""))} | J16: {=IF(OR(A16="",B16=""),"",IFERROR(INDEX('All Foods'!$J:$J,MATCH(A16,'All Foods'!$A:$A,0))*B16/100,""))} | K16: {=IF(OR(A16="",B16=""),"",IFERROR(INDEX('All Foods'!$K:$K,MATCH(A16,'All Foods'!$A:$A,0))*B16/100,""))}
C17: {=IF(OR(A17="",B17=""),"",IFERROR(INDEX('All Foods'!$C:$C,MATCH(A17,'All Foods'!$A:$A,0))*B17/100,""))} | D17: {=IF(OR(A17="",B17=""),"",IFERROR(INDEX('All Foods'!$D:$D,MATCH(A17,'All Foods'!$A:$A,0))*B17/100,""))} | E17: {=IF(OR(A17="",B17=""),"",IFERROR(INDEX('All Foods'!$E:$E,MATCH(A17,'All Foods'!$A:$A,0))*B17/100,""))} | F17: {=IF(OR(A17="",B17=""),"",IFERROR(INDEX('All Foods'!$F:$F,MATCH(A17,'All Foods'!$A:$A,0))*B17/100,""))} | G17: {=IF(OR(A17="",B17=""),"",IFERROR(INDEX('All Foods'!$G:$G,MATCH(A17,'All Foods'!$A:$A,0))*B17/100,""))} | H17: {=IF(OR(A17="",B17=""),"",IFERROR(INDEX('All Foods'!$H:$H,MATCH(A17,'All Foods'!$A:$A,0))*B17/100,""))} | I17: {=IF(OR(A17="",B17=""),"",IFERROR(INDEX('All Foods'!$I:$I,MATCH(A17,'All Foods'!$A:$A,0))*B17/100,""))} | J17: {=IF(OR(A17="",B17=""),"",IFERROR(INDEX('All Foods'!$J:$J,MATCH(A17,'All Foods'!$A:$A,0))*B17/100,""))} | K17: {=IF(OR(A17="",B17=""),"",IFERROR(INDEX('All Foods'!$K:$K,MATCH(A17,'All Foods'!$A:$A,0))*B17/100,""))}
C18: {=IF(OR(A18="",B18=""),"",IFERROR(INDEX('All Foods'!$C:$C,MATCH(A18,'All Foods'!$A:$A,0))*B18/100,""))} | D18: {=IF(OR(A18="",B18=""),"",IFERROR(INDEX('All Foods'!$D:$D,MATCH(A18,'All Foods'!$A:$A,0))*B18/100,""))} | E18: {=IF(OR(A18="",B18=""),"",IFERROR(INDEX('All Foods'!$E:$E,MATCH(A18,'All Foods'!$A:$A,0))*B18/100,""))} | F18: {=IF(OR(A18="",B18=""),"",IFERROR(INDEX('All Foods'!$F:$F,MATCH(A18,'All Foods'!$A:$A,0))*B18/100,""))} | G18: {=IF(OR(A18="",B18=""),"",IFERROR(INDEX('All Foods'!$G:$G,MATCH(A18,'All Foods'!$A:$A,0))*B18/100,""))} | H18: {=IF(OR(A18="",B18=""),"",IFERROR(INDEX('All Foods'!$H:$H,MATCH(A18,'All Foods'!$A:$A,0))*B18/100,""))} | I18: {=IF(OR(A18="",B18=""),"",IFERROR(INDEX('All Foods'!$I:$I,MATCH(A18,'All Foods'!$A:$A,0))*B18/100,""))} | J18: {=IF(OR(A18="",B18=""),"",IFERROR(INDEX('All Foods'!$J:$J,MATCH(A18,'All Foods'!$A:$A,0))*B18/100,""))} | K18: {=IF(OR(A18="",B18=""),"",IFERROR(INDEX('All Foods'!$K:$K,MATCH(A18,'All Foods'!$A:$A,0))*B18/100,""))}
C19: {=IF(OR(A19="",B19=""),"",IFERROR(INDEX('All Foods'!$C:$C,MATCH(A19,'All Foods'!$A:$A,0))*B19/100,""))} | D19: {=IF(OR(A19="",B19=""),"",IFERROR(INDEX('All Foods'!$D:$D,MATCH(A19,'All Foods'!$A:$A,0))*B19/100,""))} | E19: {=IF(OR(A19="",B19=""),"",IFERROR(INDEX('All Foods'!$E:$E,MATCH(A19,'All Foods'!$A:$A,0))*B19/100,""))} | F19: {=IF(OR(A19="",B19=""),"",IFERROR(INDEX('All Foods'!$F:$F,MATCH(A19,'All Foods'!$A:$A,0))*B19/100,""))} | G19: {=IF(OR(A19="",B19=""),"",IFERROR(INDEX('All Foods'!$G:$G,MATCH(A19,'All Foods'!$A:$A,0))*B19/100,""))} | H19: {=IF(OR(A19="",B19=""),"",IFERROR(INDEX('All Foods'!$H:$H,MATCH(A19,'All Foods'!$A:$A,0))*B19/100,""))} | I19: {=IF(OR(A19="",B19=""),"",IFERROR(INDEX('All Foods'!$I:$I,MATCH(A19,'All Foods'!$A:$A,0))*B19/100,""))} | J19: {=IF(OR(A19="",B19=""),"",IFERROR(INDEX('All Foods'!$J:$J,MATCH(A19,'All Foods'!$A:$A,0))*B19/100,""))} | K19: {=IF(OR(A19="",B19=""),"",IFERROR(INDEX('All Foods'!$K:$K,MATCH(A19,'All Foods'!$A:$A,0))*B19/100,""))}
C20: {=IF(OR(A20="",B20=""),"",IFERROR(INDEX('All Foods'!$C:$C,MATCH(A20,'All Foods'!$A:$A,0))*B20/100,""))} | D20: {=IF(OR(A20="",B20=""),"",IFERROR(INDEX('All Foods'!$D:$D,MATCH(A20,'All Foods'!$A:$A,0))*B20/100,""))} | E20: {=IF(OR(A20="",B20=""),"",IFERROR(INDEX('All Foods'!$E:$E,MATCH(A20,'All Foods'!$A:$A,0))*B20/100,""))} | F20: {=IF(OR(A20="",B20=""),"",IFERROR(INDEX('All Foods'!$F:$F,MATCH(A20,'All Foods'!$A:$A,0))*B20/100,""))} | G20: {=IF(OR(A20="",B20=""),"",IFERROR(INDEX('All Foods'!$G:$G,MATCH(A20,'All Foods'!$A:$A,0))*B20/100,""))} | H20: {=IF(OR(A20="",B20=""),"",IFERROR(INDEX('All Foods'!$H:$H,MATCH(A20,'All Foods'!$A:$A,0))*B20/100,""))} | I20: {=IF(OR(A20="",B20=""),"",IFERROR(INDEX('All Foods'!$I:$I,MATCH(A20,'All Foods'!$A:$A,0))*B20/100,""))} | J20: {=IF(OR(A20="",B20=""),"",IFERROR(INDEX('All Foods'!$J:$J,MATCH(A20,'All Foods'!$A:$A,0))*B20/100,""))} | K20: {=IF(OR(A20="",B20=""),"",IFERROR(INDEX('All Foods'!$K:$K,MATCH(A20,'All Foods'!$A:$A,0))*B20/100,""))}
... C505: {=IF(OR(A505="",B505=""),"",IFERROR(INDEX('All Foods'!$C:$C,MATCH(A505,'All Foods'!$A:$A,0))*B505/100,""))} | D505: {=IF(OR(A505="",B505=""),"",IFERROR(INDEX('All Foods'!$D:$D,MATCH(A505,'All Foods'!$A:$A,0))*B505/100,""))} | E505: {=IF(OR(A505="",B505=""),"",IFERROR(INDEX('All Foods'!$E:$E,MATCH(A505,'All Foods'!$A:$A,0))*B505/100,""))} | F505: {=IF(OR(A505="",B505=""),"",IFERROR(INDEX('All Foods'!$F:$F,MATCH(A505,'All Foods'!$A:$A,0))*B505/100,""))} | G505: {=IF(OR(A505="",B505=""),"",IFERROR(INDEX('All Foods'!$G:$G,MATCH(A505,'All Foods'!$A:$A,0))*B505/100,""))} | H505: {=IF(OR(A505="",B505=""),"",IFERROR(INDEX('All Foods'!$H:$H,MATCH(A505,'All Foods'!$A:$A,0))*B505/100,""))} | I505: {=IF(OR(A505="",B505=""),"",IFERROR(INDEX('All Foods'!$I:$I,MATCH(A505,'All Foods'!$A:$A,0))*B505/100,""))} | J505: {=IF(OR(A505="",B505=""),"",IFERROR(INDEX('All Foods'!$J:$J,MATCH(A505,'All Foods'!$A:$A,0))*B505/100,""))} | K505: {=IF(OR(A505="",B505=""),"",IFERROR(INDEX('All Foods'!$K:$K,MATCH(A505,'All Foods'!$A:$A,0))*B505/100,""))}

Sheet vanilla ice cream
A1: Vanilla ice cream
A2: TOTAL | B2: =SUM(B4:B505) -> 0 | C2: =IF($B$2=0,"",SUM(C4:C505)) | D2: =IF($B$2=0,"",SUM(D4:D505)) | E2: =IF($B$2=0,"",SUM(E4:E505)) | F2: =IF($B$2=0,"",SUM(F4:F505)) | G2: =IF($B$2=0,"",SUM(G4:G505)) | H2: =IF($B$2=0,"",SUM(H4:H505)) | I2: =IF($B$2=0,"",SUM(I4:I505)) | J2: =IF($B$2=0,"",SUM(J4:J505)) | K2: =IF($B$2=0,"",SUM(K4:K505))
A3: food_name (choose) | B3: grams_eaten | C3: calories | D3: fat | E3: saturated_fat | F3: carbohydrates | G3: sugars | H3: protein | I3: fiber | J3: omega-3 | K3: omega-6
C4: {=IF(OR(A4="",B4=""),"",IFERROR(INDEX('All Foods'!$C:$C,MATCH(A4,'All Foods'!$A:$A,0))*B4/100,""))} | D4: {=IF(OR(A4="",B4=""),"",IFERROR(INDEX('All Foods'!$D:$D,MATCH(A4,'All Foods'!$A:$A,0))*B4/100,""))} | E4: {=IF(OR(A4="",B4=""),"",IFERROR(INDEX('All Foods'!$E:$E,MATCH(A4,'All Foods'!$A:$A,0))*B4/100,""))} | F4: {=IF(OR(A4="",B4=""),"",IFERROR(INDEX('All Foods'!$F:$F,MATCH(A4,'All Foods'!$A:$A,0))*B4/100,""))} | G4: {=IF(OR(A4="",B4=""),"",IFERROR(INDEX('All Foods'!$G:$G,MATCH(A4,'All Foods'!$A:$A,0))*B4/100,""))} | H4: {=IF(OR(A4="",B4=""),"",IFERROR(INDEX('All Foods'!$H:$H,MATCH(A4,'All Foods'!$A:$A,0))*B4/100,""))} | I4: {=IF(OR(A4="",B4=""),"",IFERROR(INDEX('All Foods'!$I:$I,MATCH(A4,'All Foods'!$A:$A,0))*B4/100,""))} | J4: {=IF(OR(A4="",B4=""),"",IFERROR(INDEX('All Foods'!$J:$J,MATCH(A4,'All Foods'!$A:$A,0))*B4/100,""))} | K4: {=IF(OR(A4="",B4=""),"",IFERROR(INDEX('All Foods'!$K:$K,MATCH(A4,'All Foods'!$A:$A,0))*B4/100,""))}
C5: {=IF(OR(A5="",B5=""),"",IFERROR(INDEX('All Foods'!$C:$C,MATCH(A5,'All Foods'!$A:$A,0))*B5/100,""))} | D5: {=IF(OR(A5="",B5=""),"",IFERROR(INDEX('All Foods'!$D:$D,MATCH(A5,'All Foods'!$A:$A,0))*B5/100,""))} | E5: {=IF(OR(A5="",B5=""),"",IFERROR(INDEX('All Foods'!$E:$E,MATCH(A5,'All Foods'!$A:$A,0))*B5/100,""))} | F5: {=IF(OR(A5="",B5=""),"",IFERROR(INDEX('All Foods'!$F:$F,MATCH(A5,'All Foods'!$A:$A,0))*B5/100,""))} | G5: {=IF(OR(A5="",B5=""),"",IFERROR(INDEX('All Foods'!$G:$G,MATCH(A5,'All Foods'!$A:$A,0))*B5/100,""))} | H5: {=IF(OR(A5="",B5=""),"",IFERROR(INDEX('All Foods'!$H:$H,MATCH(A5,'All Foods'!$A:$A,0))*B5/100,""))} | I5: {=IF(OR(A5="",B5=""),"",IFERROR(INDEX('All Foods'!$I:$I,MATCH(A5,'All Foods'!$A:$A,0))*B5/100,""))} | J5: {=IF(OR(A5="",B5=""),"",IFERROR(INDEX('All Foods'!$J:$J,MATCH(A5,'All Foods'!$A:$A,0))*B5/100,""))} | K5: {=IF(OR(A5="",B5=""),"",IFERROR(INDEX('All Foods'!$K:$K,MATCH(A5,'All Foods'!$A:$A,0))*B5/100,""))}
C6: {=IF(OR(A6="",B6=""),"",IFERROR(INDEX('All Foods'!$C:$C,MATCH(A6,'All Foods'!$A:$A,0))*B6/100,""))} | D6: {=IF(OR(A6="",B6=""),"",IFERROR(INDEX('All Foods'!$D:$D,MATCH(A6,'All Foods'!$A:$A,0))*B6/100,""))} | E6: {=IF(OR(A6="",B6=""),"",IFERROR(INDEX('All Foods'!$E:$E,MATCH(A6,'All Foods'!$A:$A,0))*B6/100,""))} | F6: {=IF(OR(A6="",B6=""),"",IFERROR(INDEX('All Foods'!$F:$F,MATCH(A6,'All Foods'!$A:$A,0))*B6/100,""))} | G6: {=IF(OR(A6="",B6=""),"",IFERROR(INDEX('All Foods'!$G:$G,MATCH(A6,'All Foods'!$A:$A,0))*B6/100,""))} | H6: {=IF(OR(A6="",B6=""),"",IFERROR(INDEX('All Foods'!$H:$H,MATCH(A6,'All Foods'!$A:$A,0))*B6/100,""))} | I6: {=IF(OR(A6="",B6=""),"",IFERROR(INDEX('All Foods'!$I:$I,MATCH(A6,'All Foods'!$A:$A,0))*B6/100,""))} | J6: {=IF(OR(A6="",B6=""),"",IFERROR(INDEX('All Foods'!$J:$J,MATCH(A6,'All Foods'!$A:$A,0))*B6/100,""))} | K6: {=IF(OR(A6="",B6=""),"",IFERROR(INDEX('All Foods'!$K:$K,MATCH(A6,'All Foods'!$A:$A,0))*B6/100,""))}
C7: {=IF(OR(A7="",B7=""),"",IFERROR(INDEX('All Foods'!$C:$C,MATCH(A7,'All Foods'!$A:$A,0))*B7/100,""))} | D7: {=IF(OR(A7="",B7=""),"",IFERROR(INDEX('All Foods'!$D:$D,MATCH(A7,'All Foods'!$A:$A,0))*B7/100,""))} | E7: {=IF(OR(A7="",B7=""),"",IFERROR(INDEX('All Foods'!$E:$E,MATCH(A7,'All Foods'!$A:$A,0))*B7/100,""))} | F7: {=IF(OR(A7="",B7=""),"",IFERROR(INDEX('All Foods'!$F:$F,MATCH(A7,'All Foods'!$A:$A,0))*B7/100,""))} | G7: {=IF(OR(A7="",B7=""),"",IFERROR(INDEX('All Foods'!$G:$G,MATCH(A7,'All Foods'!$A:$A,0))*B7/100,""))} | H7: {=IF(OR(A7="",B7=""),"",IFERROR(INDEX('All Foods'!$H:$H,MATCH(A7,'All Foods'!$A:$A,0))*B7/100,""))} | I7: {=IF(OR(A7="",B7=""),"",IFERROR(INDEX('All Foods'!$I:$I,MATCH(A7,'All Foods'!$A:$A,0))*B7/100,""))} | J7: {=IF(OR(A7="",B7=""),"",IFERROR(INDEX('All Foods'!$J:$J,MATCH(A7,'All Foods'!$A:$A,0))*B7/100,""))} | K7: {=IF(OR(A7="",B7=""),"",IFERROR(INDEX('All Foods'!$K:$K,MATCH(A7,'All Foods'!$A:$A,0))*B7/100,""))}
C8: {=IF(OR(A8="",B8=""),"",IFERROR(INDEX('All Foods'!$C:$C,MATCH(A8,'All Foods'!$A:$A,0))*B8/100,""))} | D8: {=IF(OR(A8="",B8=""),"",IFERROR(INDEX('All Foods'!$D:$D,MATCH(A8,'All Foods'!$A:$A,0))*B8/100,""))} | E8: {=IF(OR(A8="",B8=""),"",IFERROR(INDEX('All Foods'!$E:$E,MATCH(A8,'All Foods'!$A:$A,0))*B8/100,""))} | F8: {=IF(OR(A8="",B8=""),"",IFERROR(INDEX('All Foods'!$F:$F,MATCH(A8,'All Foods'!$A:$A,0))*B8/100,""))} | G8: {=IF(OR(A8="",B8=""),"",IFERROR(INDEX('All Foods'!$G:$G,MATCH(A8,'All Foods'!$A:$A,0))*B8/100,""))} | H8: {=IF(OR(A8="",B8=""),"",IFERROR(INDEX('All Foods'!$H:$H,MATCH(A8,'All Foods'!$A:$A,0))*B8/100,""))} | I8: {=IF(OR(A8="",B8=""),"",IFERROR(INDEX('All Foods'!$I:$I,MATCH(A8,'All Foods'!$A:$A,0))*B8/100,""))} | J8: {=IF(OR(A8="",B8=""),"",IFERROR(INDEX('All Foods'!$J:$J,MATCH(A8,'All Foods'!$A:$A,0))*B8/100,""))} | K8: {=IF(OR(A8="",B8=""),"",IFERROR(INDEX('All Foods'!$K:$K,MATCH(A8,'All Foods'!$A:$A,0))*B8/100,""))}
C9: {=IF(OR(A9="",B9=""),"",IFERROR(INDEX('All Foods'!$C:$C,MATCH(A9,'All Foods'!$A:$A,0))*B9/100,""))} | D9: {=IF(OR(A9="",B9=""),"",IFERROR(INDEX('All Foods'!$D:$D,MATCH(A9,'All Foods'!$A:$A,0))*B9/100,""))} | E9: {=IF(OR(A9="",B9=""),"",IFERROR(INDEX('All Foods'!$E:$E,MATCH(A9,'All Foods'!$A:$A,0))*B9/100,""))} | F9: {=IF(OR(A9="",B9=""),"",IFERROR(INDEX('All Foods'!$F:$F,MATCH(A9,'All Foods'!$A:$A,0))*B9/100,""))} | G9: {=IF(OR(A9="",B9=""),"",IFERROR(INDEX('All Foods'!$G:$G,MATCH(A9,'All Foods'!$A:$A,0))*B9/100,""))} | H9: {=IF(OR(A9="",B9=""),"",IFERROR(INDEX('All Foods'!$H:$H,MATCH(A9,'All Foods'!$A:$A,0))*B9/100,""))} | I9: {=IF(OR(A9="",B9=""),"",IFERROR(INDEX('All Foods'!$I:$I,MATCH(A9,'All Foods'!$A:$A,0))*B9/100,""))} | J9: {=IF(OR(A9="",B9=""),"",IFERROR(INDEX('All Foods'!$J:$J,MATCH(A9,'All Foods'!$A:$A,0))*B9/100,""))} | K9: {=IF(OR(A9="",B9=""),"",IFERROR(INDEX('All Foods'!$K:$K,MATCH(A9,'All Foods'!$A:$A,0))*B9/100,""))}
C10: {=IF(OR(A10="",B10=""),"",IFERROR(INDEX('All Foods'!$C:$C,MATCH(A10,'All Foods'!$A:$A,0))*B10/100,""))} | D10: {=IF(OR(A10="",B10=""),"",IFERROR(INDEX('All Foods'!$D:$D,MATCH(A10,'All Foods'!$A:$A,0))*B10/100,""))} | E10: {=IF(OR(A10="",B10=""),"",IFERROR(INDEX('All Foods'!$E:$E,MATCH(A10,'All Foods'!$A:$A,0))*B10/100,""))} | F10: {=IF(OR(A10="",B10=""),"",IFERROR(INDEX('All Foods'!$F:$F,MATCH(A10,'All Foods'!$A:$A,0))*B10/100,""))} | G10: {=IF(OR(A10="",B10=""),"",IFERROR(INDEX('All Foods'!$G:$G,MATCH(A10,'All Foods'!$A:$A,0))*B10/100,""))} | H10: {=IF(OR(A10="",B10=""),"",IFERROR(INDEX('All Foods'!$H:$H,MATCH(A10,'All Foods'!$A:$A,0))*B10/100,""))} | I10: {=IF(OR(A10="",B10=""),"",IFERROR(INDEX('All Foods'!$I:$I,MATCH(A10,'All Foods'!$A:$A,0))*B10/100,""))} | J10: {=IF(OR(A10="",B10=""),"",IFERROR(INDEX('All Foods'!$J:$J,MATCH(A10,'All Foods'!$A:$A,0))*B10/100,""))} | K10: {=IF(OR(A10="",B10=""),"",IFERROR(INDEX('All Foods'!$K:$K,MATCH(A10,'All Foods'!$A:$A,0))*B10/100,""))}
C11: {=IF(OR(A11="",B11=""),"",IFERROR(INDEX('All Foods'!$C:$C,MATCH(A11,'All Foods'!$A:$A,0))*B11/100,""))} | D11: {=IF(OR(A11="",B11=""),"",IFERROR(INDEX('All Foods'!$D:$D,MATCH(A11,'All Foods'!$A:$A,0))*B11/100,""))} | E11: {=IF(OR(A11="",B11=""),"",IFERROR(INDEX('All Foods'!$E:$E,MATCH(A11,'All Foods'!$A:$A,0))*B11/100,""))} | F11: {=IF(OR(A11="",B11=""),"",IFERROR(INDEX('All Foods'!$F:$F,MATCH(A11,'All Foods'!$A:$A,0))*B11/100,""))} | G11: {=IF(OR(A11="",B11=""),"",IFERROR(INDEX('All Foods'!$G:$G,MATCH(A11,'All Foods'!$A:$A,0))*B11/100,""))} | H11: {=IF(OR(A11="",B11=""),"",IFERROR(INDEX('All Foods'!$H:$H,MATCH(A11,'All Foods'!$A:$A,0))*B11/100,""))} | I11: {=IF(OR(A11="",B11=""),"",IFERROR(INDEX('All Foods'!$I:$I,MATCH(A11,'All Foods'!$A:$A,0))*B11/100,""))} | J11: {=IF(OR(A11="",B11=""),"",IFERROR(INDEX('All Foods'!$J:$J,MATCH(A11,'All Foods'!$A:$A,0))*B11/100,""))} | K11: {=IF(OR(A11="",B11=""),"",IFERROR(INDEX('All Foods'!$K:$K,MATCH(A11,'All Foods'!$A:$A,0))*B11/100,""))}
C12: {=IF(OR(A12="",B12=""),"",IFERROR(INDEX('All Foods'!$C:$C,MATCH(A12,'All Foods'!$A:$A,0))*B12/100,""))} | D12: {=IF(OR(A12="",B12=""),"",IFERROR(INDEX('All Foods'!$D:$D,MATCH(A12,'All Foods'!$A:$A,0))*B12/100,""))} | E12: {=IF(OR(A12="",B12=""),"",IFERROR(INDEX('All Foods'!$E:$E,MATCH(A12,'All Foods'!$A:$A,0))*B12/100,""))} | F12: {=IF(OR(A12="",B12=""),"",IFERROR(INDEX('All Foods'!$F:$F,MATCH(A12,'All Foods'!$A:$A,0))*B12/100,""))} | G12: {=IF(OR(A12="",B12=""),"",IFERROR(INDEX('All Foods'!$G:$G,MATCH(A12,'All Foods'!$A:$A,0))*B12/100,""))} | H12: {=IF(OR(A12="",B12=""),"",IFERROR(INDEX('All Foods'!$H:$H,MATCH(A12,'All Foods'!$A:$A,0))*B12/100,""))} | I12: {=IF(OR(A12="",B12=""),"",IFERROR(INDEX('All Foods'!$I:$I,MATCH(A12,'All Foods'!$A:$A,0))*B12/100,""))} | J12: {=IF(OR(A12="",B12=""),"",IFERROR(INDEX('All Foods'!$J:$J,MATCH(A12,'All Foods'!$A:$A,0))*B12/100,""))} | K12: {=IF(OR(A12="",B12=""),"",IFERROR(INDEX('All Foods'!$K:$K,MATCH(A12,'All Foods'!$A:$A,0))*B12/100,""))}
C13: {=IF(OR(A13="",B13=""),"",IFERROR(INDEX('All Foods'!$C:$C,MATCH(A13,'All Foods'!$A:$A,0))*B13/100,""))} | D13: {=IF(OR(A13="",B13=""),"",IFERROR(INDEX('All Foods'!$D:$D,MATCH(A13,'All Foods'!$A:$A,0))*B13/100,""))} | E13: {=IF(OR(A13="",B13=""),"",IFERROR(INDEX('All Foods'!$E:$E,MATCH(A13,'All Foods'!$A:$A,0))*B13/100,""))} | F13: {=IF(OR(A13="",B13=""),"",IFERROR(INDEX('All Foods'!$F:$F,MATCH(A13,'All Foods'!$A:$A,0))*B13/100,""))} | G13: {=IF(OR(A13="",B13=""),"",IFERROR(INDEX('All Foods'!$G:$G,MATCH(A13,'All Foods'!$A:$A,0))*B13/100,""))} | H13: {=IF(OR(A13="",B13=""),"",IFERROR(INDEX('All Foods'!$H:$H,MATCH(A13,'All Foods'!$A:$A,0))*B13/100,""))} | I13: {=IF(OR(A13="",B13=""),"",IFERROR(INDEX('All Foods'!$I:$I,MATCH(A13,'All Foods'!$A:$A,0))*B13/100,""))} | J13: {=IF(OR(A13="",B13=""),"",IFERROR(INDEX('All Foods'!$J:$J,MATCH(A13,'All Foods'!$A:$A,0))*B13/100,""))} | K13: {=IF(OR(A13="",B13=""),"",IFERROR(INDEX('All Foods'!$K:$K,MATCH(A13,'All Foods'!$A:$A,0))*B13/100,""))}
C14: {=IF(OR(A14="",B14=""),"",IFERROR(INDEX('All Foods'!$C:$C,MATCH(A14,'All Foods'!$A:$A,0))*B14/100,""))} | D14: {=IF(OR(A14="",B14=""),"",IFERROR(INDEX('All Foods'!$D:$D,MATCH(A14,'All Foods'!$A:$A,0))*B14/100,""))} | E14: {=IF(OR(A14="",B14=""),"",IFERROR(INDEX('All Foods'!$E:$E,MATCH(A14,'All Foods'!$A:$A,0))*B14/100,""))} | F14: {=IF(OR(A14="",B14=""),"",IFERROR(INDEX('All Foods'!$F:$F,MATCH(A14,'All Foods'!$A:$A,0))*B14/100,""))} | G14: {=IF(OR(A14="",B14=""),"",IFERROR(INDEX('All Foods'!$G:$G,MATCH(A14,'All Foods'!$A:$A,0))*B14/100,""))} | H14: {=IF(OR(A14="",B14=""),"",IFERROR(INDEX('All Foods'!$H:$H,MATCH(A14,'All Foods'!$A:$A,0))*B14/100,""))} | I14: {=IF(OR(A14="",B14=""),"",IFERROR(INDEX('All Foods'!$I:$I,MATCH(A14,'All Foods'!$A:$A,0))*B14/100,""))} | J14: {=IF(OR(A14="",B14=""),"",IFERROR(INDEX('All Foods'!$J:$J,MATCH(A14,'All Foods'!$A:$A,0))*B14/100,""))} | K14: {=IF(OR(A14="",B14=""),"",IFERROR(INDEX('All Foods'!$K:$K,MATCH(A14,'All Foods'!$A:$A,0))*B14/100,""))}
C15: {=IF(OR(A15="",B15=""),"",IFERROR(INDEX('All Foods'!$C:$C,MATCH(A15,'All Foods'!$A:$A,0))*B15/100,""))} | D15: {=IF(OR(A15="",B15=""),"",IFERROR(INDEX('All Foods'!$D:$D,MATCH(A15,'All Foods'!$A:$A,0))*B15/100,""))} | E15: {=IF(OR(A15="",B15=""),"",IFERROR(INDEX('All Foods'!$E:$E,MATCH(A15,'All Foods'!$A:$A,0))*B15/100,""))} | F15: {=IF(OR(A15="",B15=""),"",IFERROR(INDEX('All Foods'!$F:$F,MATCH(A15,'All Foods'!$A:$A,0))*B15/100,""))} | G15: {=IF(OR(A15="",B15=""),"",IFERROR(INDEX('All Foods'!$G:$G,MATCH(A15,'All Foods'!$A:$A,0))*B15/100,""))} | H15: {=IF(OR(A15="",B15=""),"",IFERROR(INDEX('All Foods'!$H:$H,MATCH(A15,'All Foods'!$A:$A,0))*B15/100,""))} | I15: {=IF(OR(A15="",B15=""),"",IFERROR(INDEX('All Foods'!$I:$I,MATCH(A15,'All Foods'!$A:$A,0))*B15/100,""))} | J15: {=IF(OR(A15="",B15=""),"",IFERROR(INDEX('All Foods'!$J:$J,MATCH(A15,'All Foods'!$A:$A,0))*B15/100,""))} | K15: {=IF(OR(A15="",B15=""),"",IFERROR(INDEX('All Foods'!$K:$K,MATCH(A15,'All Foods'!$A:$A,0))*B15/100,""))}
... C33: {=IF(OR(A33="",B33=""),"",IFERROR(INDEX('All Foods'!$C:$C,MATCH(A33,'All Foods'!$A:$A,0))*B33/100,""))} | D33: {=IF(OR(A33="",B33=""),"",IFERROR(INDEX('All Foods'!$D:$D,MATCH(A33,'All Foods'!$A:$A,0))*B33/100,""))} | E33: {=IF(OR(A33="",B33=""),"",IFERROR(INDEX('All Foods'!$E:$E,MATCH(A33,'All Foods'!$A:$A,0))*B33/100,""))} | F33: {=IF(OR(A33="",B33=""),"",IFERROR(INDEX('All Foods'!$F:$F,MATCH(A33,'All Foods'!$A:$A,0))*B33/100,""))} | G33: {=IF(OR(A33="",B33=""),"",IFERROR(INDEX('All Foods'!$G:$G,MATCH(A33,'All Foods'!$A:$A,0))*B33/100,""))} | H33: {=IF(OR(A33="",B33=""),"",IFERROR(INDEX('All Foods'!$H:$H,MATCH(A33,'All Foods'!$A:$A,0))*B33/100,""))} | I33: {=IF(OR(A33="",B33=""),"",IFERROR(INDEX('All Foods'!$I:$I,MATCH(A33,'All Foods'!$A:$A,0))*B33/100,""))} | J33: {=IF(OR(A33="",B33=""),"",IFERROR(INDEX('All Foods'!$J:$J,MATCH(A33,'All Foods'!$A:$A,0))*B33/100,""))} | K33: {=IF(OR(A33="",B33=""),"",IFERROR(INDEX('All Foods'!$K:$K,MATCH(A33,'All Foods'!$A:$A,0))*B33/100,""))}
B34: ="" | C34: ="" | D34: ="" | E34: ="" | F34: ="" | G34: ="" | H34: ="" | I34: ="" | ... K34: =""
C35: {=IF(OR(A35="",B35=""),"",IFERROR(INDEX('All Foods'!$C:$C,MATCH(A35,'All Foods'!$A:$A,0))*B35/100,""))} | D35: {=IF(OR(A35="",B35=""),"",IFERROR(INDEX('All Foods'!$D:$D,MATCH(A35,'All Foods'!$A:$A,0))*B35/100,""))} | E35: {=IF(OR(A35="",B35=""),"",IFERROR(INDEX('All Foods'!$E:$E,MATCH(A35,'All Foods'!$A:$A,0))*B35/100,""))} | F35: {=IF(OR(A35="",B35=""),"",IFERROR(INDEX('All Foods'!$F:$F,MATCH(A35,'All Foods'!$A:$A,0))*B35/100,""))} | G35: {=IF(OR(A35="",B35=""),"",IFERROR(INDEX('All Foods'!$G:$G,MATCH(A35,'All Foods'!$A:$A,0))*B35/100,""))} | H35: {=IF(OR(A35="",B35=""),"",IFERROR(INDEX('All Foods'!$H:$H,MATCH(A35,'All Foods'!$A:$A,0))*B35/100,""))} | I35: {=IF(OR(A35="",B35=""),"",IFERROR(INDEX('All Foods'!$I:$I,MATCH(A35,'All Foods'!$A:$A,0))*B35/100,""))} | J35: {=IF(OR(A35="",B35=""),"",IFERROR(INDEX('All Foods'!$J:$J,MATCH(A35,'All Foods'!$A:$A,0))*B35/100,""))} | K35: {=IF(OR(A35="",B35=""),"",IFERROR(INDEX('All Foods'!$K:$K,MATCH(A35,'All Foods'!$A:$A,0))*B35/100,""))}
C36: {=IF(OR(A36="",B36=""),"",IFERROR(INDEX('All Foods'!$C:$C,MATCH(A36,'All Foods'!$A:$A,0))*B36/100,""))} | D36: {=IF(OR(A36="",B36=""),"",IFERROR(INDEX('All Foods'!$D:$D,MATCH(A36,'All Foods'!$A:$A,0))*B36/100,""))} | E36: {=IF(OR(A36="",B36=""),"",IFERROR(INDEX('All Foods'!$E:$E,MATCH(A36,'All Foods'!$A:$A,0))*B36/100,""))} | F36: {=IF(OR(A36="",B36=""),"",IFERROR(INDEX('All Foods'!$F:$F,MATCH(A36,'All Foods'!$A:$A,0))*B36/100,""))} | G36: {=IF(OR(A36="",B36=""),"",IFERROR(INDEX('All Foods'!$G:$G,MATCH(A36,'All Foods'!$A:$A,0))*B36/100,""))} | H36: {=IF(OR(A36="",B36=""),"",IFERROR(INDEX('All Foods'!$H:$H,MATCH(A36,'All Foods'!$A:$A,0))*B36/100,""))} | I36: {=IF(OR(A36="",B36=""),"",IFERROR(INDEX('All Foods'!$I:$I,MATCH(A36,'All Foods'!$A:$A,0))*B36/100,""))} | J36: {=IF(OR(A36="",B36=""),"",IFERROR(INDEX('All Foods'!$J:$J,MATCH(A36,'All Foods'!$A:$A,0))*B36/100,""))} | K36: {=IF(OR(A36="",B36=""),"",IFERROR(INDEX('All Foods'!$K:$K,MATCH(A36,'All Foods'!$A:$A,0))*B36/100,""))}
C37: {=IF(OR(A37="",B37=""),"",IFERROR(INDEX('All Foods'!$C:$C,MATCH(A37,'All Foods'!$A:$A,0))*B37/100,""))} | D37: {=IF(OR(A37="",B37=""),"",IFERROR(INDEX('All Foods'!$D:$D,MATCH(A37,'All Foods'!$A:$A,0))*B37/100,""))} | E37: {=IF(OR(A37="",B37=""),"",IFERROR(INDEX('All Foods'!$E:$E,MATCH(A37,'All Foods'!$A:$A,0))*B37/100,""))} | F37: {=IF(OR(A37="",B37=""),"",IFERROR(INDEX('All Foods'!$F:$F,MATCH(A37,'All Foods'!$A:$A,0))*B37/100,""))} | G37: {=IF(OR(A37="",B37=""),"",IFERROR(INDEX('All Foods'!$G:$G,MATCH(A37,'All Foods'!$A:$A,0))*B37/100,""))} | H37: {=IF(OR(A37="",B37=""),"",IFERROR(INDEX('All Foods'!$H:$H,MATCH(A37,'All Foods'!$A:$A,0))*B37/100,""))} | I37: {=IF(OR(A37="",B37=""),"",IFERROR(INDEX('All Foods'!$I:$I,MATCH(A37,'All Foods'!$A:$A,0))*B37/100,""))} | J37: {=IF(OR(A37="",B37=""),"",IFERROR(INDEX('All Foods'!$J:$J,MATCH(A37,'All Foods'!$A:$A,0))*B37/100,""))} | K37: {=IF(OR(A37="",B37=""),"",IFERROR(INDEX('All Foods'!$K:$K,MATCH(A37,'All Foods'!$A:$A,0))*B37/100,""))}
C38: {=IF(OR(A38="",B38=""),"",IFERROR(INDEX('All Foods'!$C:$C,MATCH(A38,'All Foods'!$A:$A,0))*B38/100,""))} | D38: {=IF(OR(A38="",B38=""),"",IFERROR(INDEX('All Foods'!$D:$D,MATCH(A38,'All Foods'!$A:$A,0))*B38/100,""))} | E38: {=IF(OR(A38="",B38=""),"",IFERROR(INDEX('All Foods'!$E:$E,MATCH(A38,'All Foods'!$A:$A,0))*B38/100,""))} | F38: {=IF(OR(A38="",B38=""),"",IFERROR(INDEX('All Foods'!$F:$F,MATCH(A38,'All Foods'!$A:$A,0))*B38/100,""))} | G38: {=IF(OR(A38="",B38=""),"",IFERROR(INDEX('All Foods'!$G:$G,MATCH(A38,'All Foods'!$A:$A,0))*B38/100,""))} | H38: {=IF(OR(A38="",B38=""),"",IFERROR(INDEX('All Foods'!$H:$H,MATCH(A38,'All Foods'!$A:$A,0))*B38/100,""))} | I38: {=IF(OR(A38="",B38=""),"",IFERROR(INDEX('All Foods'!$I:$I,MATCH(A38,'All Foods'!$A:$A,0))*B38/100,""))} | J38: {=IF(OR(A38="",B38=""),"",IFERROR(INDEX('All Foods'!$J:$J,MATCH(A38,'All Foods'!$A:$A,0))*B38/100,""))} | K38: {=IF(OR(A38="",B38=""),"",IFERROR(INDEX('All Foods'!$K:$K,MATCH(A38,'All Foods'!$A:$A,0))*B38/100,""))}
C39: {=IF(OR(A39="",B39=""),"",IFERROR(INDEX('All Foods'!$C:$C,MATCH(A39,'All Foods'!$A:$A,0))*B39/100,""))} | D39: {=IF(OR(A39="",B39=""),"",IFERROR(INDEX('All Foods'!$D:$D,MATCH(A39,'All Foods'!$A:$A,0))*B39/100,""))} | E39: {=IF(OR(A39="",B39=""),"",IFERROR(INDEX('All Foods'!$E:$E,MATCH(A39,'All Foods'!$A:$A,0))*B39/100,""))} | F39: {=IF(OR(A39="",B39=""),"",IFERROR(INDEX('All Foods'!$F:$F,MATCH(A39,'All Foods'!$A:$A,0))*B39/100,""))} | G39: {=IF(OR(A39="",B39=""),"",IFERROR(INDEX('All Foods'!$G:$G,MATCH(A39,'All Foods'!$A:$A,0))*B39/100,""))} | H39: {=IF(OR(A39="",B39=""),"",IFERROR(INDEX('All Foods'!$H:$H,MATCH(A39,'All Foods'!$A:$A,0))*B39/100,""))} | I39: {=IF(OR(A39="",B39=""),"",IFERROR(INDEX('All Foods'!$I:$I,MATCH(A39,'All Foods'!$A:$A,0))*B39/100,""))} | J39: {=IF(OR(A39="",B39=""),"",IFERROR(INDEX('All Foods'!$J:$J,MATCH(A39,'All Foods'!$A:$A,0))*B39/100,""))} | K39: {=IF(OR(A39="",B39=""),"",IFERROR(INDEX('All Foods'!$K:$K,MATCH(A39,'All Foods'!$A:$A,0))*B39/100,""))}
C40: {=IF(OR(A40="",B40=""),"",IFERROR(INDEX('All Foods'!$C:$C,MATCH(A40,'All Foods'!$A:$A,0))*B40/100,""))} | D40: {=IF(OR(A40="",B40=""),"",IFERROR(INDEX('All Foods'!$D:$D,MATCH(A40,'All Foods'!$A:$A,0))*B40/100,""))} | E40: {=IF(OR(A40="",B40=""),"",IFERROR(INDEX('All Foods'!$E:$E,MATCH(A40,'All Foods'!$A:$A,0))*B40/100,""))} | F40: {=IF(OR(A40="",B40=""),"",IFERROR(INDEX('All Foods'!$F:$F,MATCH(A40,'All Foods'!$A:$A,0))*B40/100,""))} | G40: {=IF(OR(A40="",B40=""),"",IFERROR(INDEX('All Foods'!$G:$G,MATCH(A40,'All Foods'!$A:$A,0))*B40/100,""))} | H40: {=IF(OR(A40="",B40=""),"",IFERROR(INDEX('All Foods'!$H:$H,MATCH(A40,'All Foods'!$A:$A,0))*B40/100,""))} | I40: {=IF(OR(A40="",B40=""),"",IFERROR(INDEX('All Foods'!$I:$I,MATCH(A40,'All Foods'!$A:$A,0))*B40/100,""))} | J40: {=IF(OR(A40="",B40=""),"",IFERROR(INDEX('All Foods'!$J:$J,MATCH(A40,'All Foods'!$A:$A,0))*B40/100,""))} | K40: {=IF(OR(A40="",B40=""),"",IFERROR(INDEX('All Foods'!$K:$K,MATCH(A40,'All Foods'!$A:$A,0))*B40/100,""))}
C41: {=IF(OR(A41="",B41=""),"",IFERROR(INDEX('All Foods'!$C:$C,MATCH(A41,'All Foods'!$A:$A,0))*B41/100,""))} | D41: {=IF(OR(A41="",B41=""),"",IFERROR(INDEX('All Foods'!$D:$D,MATCH(A41,'All Foods'!$A:$A,0))*B41/100,""))} | E41: {=IF(OR(A41="",B41=""),"",IFERROR(INDEX('All Foods'!$E:$E,MATCH(A41,'All Foods'!$A:$A,0))*B41/100,""))} | F41: {=IF(OR(A41="",B41=""),"",IFERROR(INDEX('All Foods'!$F:$F,MATCH(A41,'All Foods'!$A:$A,0))*B41/100,""))} | G41: {=IF(OR(A41="",B41=""),"",IFERROR(INDEX('All Foods'!$G:$G,MATCH(A41,'All Foods'!$A:$A,0))*B41/100,""))} | H41: {=IF(OR(A41="",B41=""),"",IFERROR(INDEX('All Foods'!$H:$H,MATCH(A41,'All Foods'!$A:$A,0))*B41/100,""))} | I41: {=IF(OR(A41="",B41=""),"",IFERROR(INDEX('All Foods'!$I:$I,MATCH(A41,'All Foods'!$A:$A,0))*B41/100,""))} | J41: {=IF(OR(A41="",B41=""),"",IFERROR(INDEX('All Foods'!$J:$J,MATCH(A41,'All Foods'!$A:$A,0))*B41/100,""))} | K41: {=IF(OR(A41="",B41=""),"",IFERROR(INDEX('All Foods'!$K:$K,MATCH(A41,'All Foods'!$A:$A,0))*B41/100,""))}
